<mujoco model="arm.SLDASM">
  <compiler angle="radian" autolimits="true"/>
  <option noslip_iterations="2" cone="elliptic" impratio="50">
    <!-- <flag gravity="disable"/> -->
    <!-- <flag passive="disable"/> -->
    <flag multiccd="enable" />
  </option>
  <!-- <statistic meansize="0.103375" extent="0.820674" center="-0.000696085 0.000716649 0.342986"/> -->
  
  <default>
    <!-- 设置所有关节默认阻尼 -->
    <joint damping="0.01" stiffness="0.01"/>
    <position kp="100"/>
  </default>
  
  <asset>
    <mesh name="base_link" file="base_link.STL"/>
    <mesh name="link1" file="link1.STL"/>
    <mesh name="link2" file="link2.STL"/>
    <mesh name="link3" file="link3.STL"/>
    <mesh name="link4" file="link4.STL"/>
    <mesh name="link5" file="link5.STL"/>
    <mesh name="link6" file="link6.STL"/>
    <mesh name="link7" file="link7.STL"/>
    <mesh name="gripper_l" file="gripper_l.STL"/>
    <mesh name="gripper_r" file="gripper_r.STL"/>
  </asset>  <worldbody>
    <!-- Overhead camera mounted above the scene -->
    <camera name="overhead_camera" pos="0 0 1.5" xyaxes="1 0 0 0 1 0"/>
    <light name="overhead_light" pos="0 0 1.5" castshadow="false"/>
    <geom type="mesh" rgba="1 1 1 1" mesh="base_link"/>
    <body name="link1">
      <inertial pos="-1.01502e-06 -0.00315105 0.0431262" quat="0.704635 0.0582641 -0.038985 0.706098" mass="0.363576" diaginertia="9.56788e-05 7.78423e-05 7.69165e-05"/>
      <joint name="joint_link1" pos="0 0 0" axis="0 0 -1" range="-6.2831852 6.2831852"/>
      <geom type="mesh" rgba="0.752941 0.752941 0.752941 1" mesh="link1"/>
      <body name="link2" pos="0 0 0.048" quat="0.707105 0.707108 0 0">
        <inertial pos="4.84416e-05 0.060778 1.93033e-05" quat="0.709402 -0.00153027 0.00354105 0.704794" mass="0.345274" diaginertia="8.8169e-05 8.23659e-05 7.40042e-05"/>
        <joint name="joint_link2" pos="0 0 0" axis="0 0 -1" range="-1.5708 1.5708"/>
        <geom type="mesh" rgba="0.752941 0.752941 0.752941 1" mesh="link2"/>
        <body name="link3" pos="0 0.094 0" quat="0.707105 -0.707108 0 0">
          <inertial pos="0.00231671 1.99517e-05 0.123131" quat="0.999896 0.000413564 0.0144106 0.000241483" mass="0.420046" diaginertia="0.000125858 0.00011213 8.58521e-05"/>
          <joint name="joint_link3" pos="0 0 0" axis="0 0 -1" range="-6.2831852 6.2831852"/>
          <geom type="mesh" rgba="0.752941 0.752941 0.752941 1" mesh="link3"/>
          <body name="link4" pos="0 0 0.146" quat="0.707107 0 0.707107 0">
            <inertial pos="-0.0787171 0.000283571 -0.000118132" quat="0.487732 0.504794 0.51249 0.494626" mass="0.530694" diaginertia="0.000349053 0.000264016 0.000200715"/>
            <joint name="joint_link4" pos="0 0 0" axis="0 0 -1" range="-1.5708 1.5708"/>
            <geom type="mesh" rgba="0.752941 0.752941 0.752941 1" mesh="link4"/>
            <body name="link5" pos="-0.1275 0 0" quat="0.707107 0 -0.707107 0">
              <inertial pos="-0.000555169 -1.36007e-08 0.0129923" quat="0.482896 0.516538 0.516538 0.482896" mass="0.1001848" diaginertia="4.66972e-05 3.42929e-05 2.25957e-05"/>
              <joint name="joint_link5" pos="0 0 0" axis="0 0 -1" range="-6.2831852 6.2831852"/>
              <geom type="mesh" rgba="0.752941 0.752941 0.752941 1" mesh="link5"/>
              <body name="link6" pos="0 0 0.0415" quat="0.707107 0 0.707107 0">
                <inertial pos="-0.0296928 0.00138012 0.000664094" quat="0.474571 0.554121 0.374767 0.572086" mass="0.617362" diaginertia="0.000188386 0.000187871 0.000129882"/>
                <joint name="joint_link6" pos="0 0 0" axis="0 0 -1" range="-1.5708 1.5708"/>
                <geom type="mesh" rgba="0.752941 0.752941 0.752941 1" mesh="link6"/>
                  <body name="link7" pos="-0.059 0 -0.0007" quat="-0.500002 0.5 0.5 0.499998">
                  <inertial pos="-2.75193e-06 -0.0837463 0.000611285" quat="0.710474 0.703513 0.0121989 -0.0121333" mass="0.607928" diaginertia="0.000564844 0.000382701 0.000264212"/>
                  <joint name="joint_link7" pos="0 0 0" axis="0 0 -1" range="-1.5708 1.5708"/>
                  <!-- <joint name="joint_link7" pos="0 0 0" axis="0 1 0" range="-1.5708 1.5708"/> -->
                  <geom type="mesh" rgba="0.752941 0.752941 0.752941 1" mesh="link7"/>
                  <!-- Wrist camera mounted on link7 -->
                  <camera name="wrist_camera" pos="-0.04 -0.05 0" xyaxes="-1 0 0 0 0 1"/>
                  <body name="gripper_l" pos="0 -0.105 -0.0039975" quat="0 1 0 0">
                    <inertial pos="-0.00323360 0.0218652 0.0128604" mass="0.1029366" diaginertia="1.82575e-05 1.47403e-05 1.08564e-05"/>
                    <joint name="joint_gripper_l" pos="0 0 0" axis="0 0 1" type="slide" range="-0.005 0.055"/>
                    <!-- <geom type="mesh" class="visual" rgba="0.752941 0.752941 0.752941 1" mesh="gripper_l"/> -->
                    <geom type="box" pos="0.005 0.07 0.005" size="0.01 0.05 0.01" friction="1 1 1"/>
                    <!-- <geom name="gripper_l_visual" type="box" pos="0.005 0.07 0.005" size="0.01 0.05 0.01" rgba="0.75 0.75 0.75 1" contype="0" conaffinity="0" group="1"/>
                    <geom name="l_pad_1" type="box" pos="0.005 0.04 0.005" size="0.012 0.006 0.012"
                          friction="2.0 0.2 0.02" solref="0.01 1"
                          rgba="1 0 0 0.5"/>

                    <geom name="l_pad_2" type="box" pos="0.005 0.10 0.005" size="0.012 0.006 0.012"
                          friction="2.0 0.2 0.02" solref="0.01 1"
                          rgba="1 0 0 0.5"/>
                          <geom name="l_pad3" type="box" pos="0.005 0.07 0.005" size="0.012 0.006 0.012"
                    friction="2.0 0.2 0.02" solref="0.01 1"
                    rgba="1 0 0 0.5"/> -->
                  </body>
                  <body name="gripper_r" pos="0 -0.105 0.0053984" quat="0 1 0 0">
                    <inertial pos="0.00323360 0.0218652 -0.0128604" mass="0.1029366" diaginertia="1.82575e-05 1.47403e-05 1.08564e-05"/>
                    <joint name="joint_gripper_r" pos="0 0 0" axis="0 0 -1" type="slide" range="-0.005 0.055"/>
                    <!-- <geom type="mesh" rgba="0.752941 0.752941 0.752941 1" mesh="gripper_r" condim="6" friction="1 1e-3 1e-3" solref=".01 1"/> -->
                    <geom type="box" pos="0.005 0.07 -0.005" size="0.01 0.05 0.01" friction="1 1 1"/>
                    <!-- <geom name="gripper_r_visual" type="box" pos="0.005 0.07 0.005" size="0.01 0.05 0.01" rgba="0.75 0.75 0.75 1" contype="0" conaffinity="0" group="1"/>
                    <geom name="r_pad_1" type="box" pos="0.005 0.04 0.005" size="0.012 0.006 0.012"
                          friction="2.0 0.2 0.02" solref="0.01 1"
                          rgba="1 0 0 0.5"/>

                    <geom name="r_pad_2" type="box" pos="0.005 0.10 0.005" size="0.012 0.006 0.012"
                          friction="2.0 0.2 0.02" solref="0.01 1"
                          rgba="1 0 0 0.5"/>
                    <geom name="r_pad_3" type="box" pos="0.005 0.07 0.005" size="0.012 0.006 0.012"
                    friction="2.0 0.2 0.02" solref="0.01 1"
                    rgba="1 0 0 0.5"/> -->
                  </body>
                </body>
              </body>
            </body>
          </body>
        </body>
      </body>
    </body>
    <body mocap="true" name="target_mocap" pos="0 0 0">
      <site name="target_site" pos="0 0 0" size="0.05" rgba="1 0 0 0.5" />
    </body>

    <body name="cube" pos="0.3 0 0.05">
      <geom type="box" size="0.03 0.03 0.03" rgba="0.8 0.2 0.2 1" mass="0.01"/>
      <!-- <inertial pos="0 0 0.0" /> -->
      <!-- <joint name="cube_joint" type="free"/> -->
      <freejoint/> 
    </body>
    <body name="plane" pos="0 0 0">
      <geom type="plane" size="10 10 0.01" rgba="0.5 0.5 0.5 1"/>
    </body>

    <body name="wall_frame">
      <geom name="wall_top" type="box" pos="-0.3 0.1 0.05" size="0.1 0.01 0.05" rgba="0.6 0.6 0.6 1"/>
      <geom name="wall_bottom" type="box" pos="-0.3 -0.1 0.05" size="0.1 0.01 0.05" rgba="0.6 0.6 0.6 1"/>
      <geom name="wall_left" type="box" pos="-0.2 0 0.05" size="0.01 0.1 0.05" rgba="0.6 0.6 0.6 1"/>
      <geom name="wall_right" type="box" pos="-0.4 0 0.05" size="0.01 0.1 0.05" rgba="0.6 0.6 0.6 1"/>
    </body>
    
  </worldbody>

  <contact>
    <!-- 关闭所有关节之间的碰撞 -->
    <exclude body1="link1" body2="link2"/>
    <exclude body1="link2" body2="link3"/>
    <exclude body1="link3" body2="link4"/>
    <exclude body1="link4" body2="link5"/>
    <exclude body1="link5" body2="link6"/>
    <exclude body1="link6" body2="link7"/>
    <exclude body1="link7" body2="gripper_l"/>
    <exclude body1="link7" body2="gripper_r"/>
    <exclude body1="gripper_l" body2="gripper_r"/>
  </contact>
  <equality>
    <joint joint1="joint_gripper_l" joint2="joint_gripper_r" polycoef="0 1 0 0 0"/>
  </equality>
  <actuator>
    <position name="act_joint_link1" joint="joint_link1" kp="50" dampratio="0.5"/>
    <position name="act_joint_link2" joint="joint_link2" kp="50" dampratio="0.5"/>
    <position name="act_joint_link3" joint="joint_link3" kp="30" dampratio="0.5"/>
    <position name="act_joint_link4" joint="joint_link4" kp="30" dampratio="0.5"/>
    <position name="act_joint_link5" joint="joint_link5" kp="10" dampratio="0.5"/>
    <position name="act_joint_link6" joint="joint_link6" kp="10" dampratio="0.5"/>
    <position name="act_joint_link7" joint="joint_link7" kp="10" dampratio="0.5"/>
    <!-- <position name="act_gripper_l" joint="joint_gripper_l" kp="200" ctrlrange="0 0.05"/>
    <position name="act_gripper_r" joint="joint_gripper_r" kp="200" ctrlrange="0 0.05"/> -->
    <!-- <motor name="motor_joint_link1" joint="joint_link1"/>
    <motor name="motor_joint_link2" joint="joint_link2"/>
    <motor name="motor_joint_link3" joint="joint_link3"/>
    <motor name="motor_joint_link4" joint="joint_link4"/>
    <motor name="motor_joint_link5" joint="joint_link5"/>
    <motor name="motor_joint_link6" joint="joint_link6"/>
    <motor name="motor_joint_link7" joint="joint_link7"/> -->
    <motor name="motor_gripper_l" joint="joint_gripper_l"/>
    <motor name="motor_gripper_r" joint="joint_gripper_r"/>
  </actuator>
</mujoco>
